<?xml version="1.0" encoding="utf-8"?>
<!-- This URDF was automatically created by SolidWorks to URDF Exporter! Originally created by Stephen Brawner (brawner@gmail.com) 
     Commit Version: 1.6.0-1-g15f4949  Build Version: 1.6.7594.29634
     For more information, please see http://wiki.ros.org/sw_urdf_exporter -->
<robot
  name="sly">
  <link
    name="base_link">
    <inertial>
      <origin
        xyz="-1.579E-05 -0.00013599 0.23643132"
        rpy="0 0 0" />
      <mass
        value="45" />
      <inertia
        ixx="2.9337"
        ixy="0.0080257"
        ixz="-0.00019718"
        iyy="11.131"
        iyz="-0.0012284"
        izz="8.5524" />
    </inertial>
    <visual>
      <origin
        xyz="0 0 0"
        rpy="0 0 0" />
      <geometry>
        <mesh
          filename="package://sly/meshes/base_link.STL" />
      </geometry>
      <material
        name="">
        <color
          rgba="0.75294 0.75294 0.75294 1" />
      </material>
    </visual>
    <collision>
      <origin
        xyz="0 0 0"
        rpy="0 0 0" />
      <geometry>
        <mesh
          filename="package://sly/meshes/base_link.STL" />
      </geometry>
    </collision>
  </link>
  <link
    name="wheel_0">
    <inertial>
      <origin
        xyz="0 0 0"
        rpy="0 0 0" />
      <mass
        value="6.5" />
      <inertia
        ixx="0.058691"
        ixy="0"
        ixz="0"
        iyy="0.58691"
        iyz="0"
        izz="0.10055" />
    </inertial>
    <visual>
      <origin
        xyz="0 0 0"
        rpy="0 0 0" />
      <geometry>
        <mesh
          filename="package://sly/meshes/wheel_0.STL" />
      </geometry>
      <material
        name="">
        <color
          rgba="0.29804 0.29804 0.29804 1" />
      </material>
    </visual>
    <collision>
      <origin
        xyz="0 0 0"
        rpy="0 0 0" />
      <geometry>
        <mesh
          filename="package://sly/meshes/wheel_0.STL" />
      </geometry>
    </collision>
  </link>
  <joint
    name="axial_0_0"
    type="continuous">
    <origin
      xyz="0.2761 -0.17457 0.1778"
      rpy="1.5708 0 3.1416" />
    <parent
      link="base_link" />
    <child
      link="wheel_0" />
    <axis
      xyz="0 0 -1" />
  </joint>
  <link
    name="wheel_1">
    <inertial>
      <origin
        xyz="0 0 0"
        rpy="0 0 0" />
      <mass
        value="6.5" />
      <inertia
        ixx="0.058691"
        ixy="0"
        ixz="0"
        iyy="0.058691"
        iyz="0"
        izz="0.10055" />
    </inertial>
    <visual>
      <origin
        xyz="0 0 0"
        rpy="0 0 0" />
      <geometry>
        <mesh
          filename="package://sly/meshes/wheel_1.STL" />
      </geometry>
      <material
        name="">
        <color
          rgba="0.29804 0.29804 0.29804 1" />
      </material>
    </visual>
    <collision>
      <origin
        xyz="0 0 0"
        rpy="0 0 0" />
      <geometry>
        <mesh
          filename="package://sly/meshes/wheel_1.STL" />
      </geometry>
    </collision>
  </link>
  <joint
    name="axial_0_1"
    type="continuous">
    <origin
      xyz="0.276098000805913 0.17467779424094 0.1778"
      rpy="-1.5707963267949 0 0" />
    <parent
      link="base_link" />
    <child
      link="wheel_1" />
    <axis
      xyz="0 0 -1" />
  </joint>
  <link
    name="wheel_2">
    <inertial>
      <origin
        xyz="0 0 0"
        rpy="0 0 0" />
      <mass
        value="6.5" />
      <inertia
        ixx="0.058691"
        ixy="0"
        ixz="0"
        iyy="0.058691"
        iyz="0"
        izz="0.10055" />
    </inertial>
    <visual>
      <origin
        xyz="0 0 0"
        rpy="0 0 0" />
      <geometry>
        <mesh
          filename="package://sly/meshes/wheel_2.STL" />
      </geometry>
      <material
        name="">
        <color
          rgba="0.29804 0.29804 0.29804 1" />
      </material>
    </visual>
    <collision>
      <origin
        xyz="0 0 0"
        rpy="0 0 0" />
      <geometry>
        <mesh
          filename="package://sly/meshes/wheel_2.STL" />
      </geometry>
    </collision>
  </link>
  <joint
    name="axial_1_0"
    type="continuous">
    <origin
      xyz="-0.2761 0.17448 0.1778"
      rpy="-1.5708 0 0" />
    <parent
      link="base_link" />
    <child
      link="wheel_2" />
    <axis
      xyz="0 0 -1" />
  </joint>
  <link
    name="wheel_3">
    <inertial>
      <origin
        xyz="0 0 0"
        rpy="0 0 0" />
      <mass
        value="6.5" />
      <inertia
        ixx="0.058691"
        ixy="0"
        ixz="0"
        iyy="0.058691"
        iyz="0"
        izz="0.10055" />
    </inertial>
    <visual>
      <origin
        xyz="0 0 0"
        rpy="0 0 0" />
      <geometry>
        <mesh
          filename="package://sly/meshes/wheel_3.STL" />
      </geometry>
      <material
        name="">
        <color
          rgba="0.29804 0.29804 0.29804 1" />
      </material>
    </visual>
    <collision>
      <origin
        xyz="0 0 0"
        rpy="0 0 0" />
      <geometry>
        <mesh
          filename="package://sly/meshes/wheel_3.STL" />
      </geometry>
    </collision>
  </link>
  <joint
    name="axial_1_1"
    type="continuous">
    <origin
      xyz="-0.2761 -0.17477 0.1778"
      rpy="-1.5708 0 0" />
    <parent
      link="base_link" />
    <child
      link="wheel_3" />
    <axis
      xyz="0 0 -1" />
  </joint>
</robot>