<sdf version='1.7'>
  <model name='sly'>
    <link name='base_link'>
      <inertial>
        <pose>-1.6e-05 -0.000136 0.236431 0 -0 0</pose>
        <mass>45</mass>
        <inertia>
          <ixx>2.9337</ixx>
          <ixy>0.0080257</ixy>
          <ixz>-0.00019718</ixz>
          <iyy>11.131</iyy>
          <iyz>-0.0012284</iyz>
          <izz>8.5524</izz>
        </inertia>
      </inertial>
      <collision name='base_link_collision'>
        <pose>0 0 0 0 -0 0</pose>
        <geometry>
          <mesh>
            <scale>1 1 1</scale>
            <uri>model://sly/meshes/base_link.STL</uri>
          </mesh>
        </geometry>
      </collision>
      <visual name='base_link_visual'>
        <pose>0 0 0 0 -0 0</pose>
        <geometry>
          <mesh>
            <scale>1 1 1</scale>
            <uri>model://sly/meshes/base_link.STL</uri>
          </mesh>
        </geometry>
      </visual>
    </link>
    <joint name='axial_0_0' type='revolute'>
      <pose relative_to='base_link'>0.2761 -0.17457 0.1778 1.5708 -0 -3.14159</pose>
      <parent>base_link</parent>
      <child>wheel_0</child>
      <axis>
        <xyz>0 0 -1</xyz>
        <limit>
          <lower>-1e+16</lower>
          <upper>1e+16</upper>
        </limit>
        <dynamics>
          <spring_reference>0</spring_reference>
          <spring_stiffness>0</spring_stiffness>
        </dynamics>
      </axis>
    </joint>
    <link name='wheel_0'>
      <pose relative_to='axial_0_0'>0 0 0 0 -0 0</pose>
      <inertial>
        <pose>0 0 0 0 -0 0</pose>
        <mass>6.5</mass>
        <inertia>
          <ixx>0.058691</ixx>
          <ixy>0</ixy>
          <ixz>0</ixz>
          <iyy>0.58691</iyy>
          <iyz>0</iyz>
          <izz>0.10055</izz>
        </inertia>
      </inertial>
      <collision name='wheel_0_collision'>
        <pose>0 0 0 0 -0 0</pose>
        <geometry>
          <mesh>
            <scale>1 1 1</scale>
            <uri>model://sly/meshes/wheel_0.STL</uri>
          </mesh>
        </geometry>
      </collision>
      <visual name='wheel_0_visual'>
        <pose>0 0 0 0 -0 0</pose>
        <geometry>
          <mesh>
            <scale>1 1 1</scale>
            <uri>model://sly/meshes/wheel_0.STL</uri>
          </mesh>
        </geometry>
      </visual>
    </link>
    <joint name='axial_0_1' type='revolute'>
      <pose relative_to='base_link'>0.276098 0.174678 0.1778 -1.5708 0 0</pose>
      <parent>base_link</parent>
      <child>wheel_1</child>
      <axis>
        <xyz>0 0 -1</xyz>
        <limit>
          <lower>-1e+16</lower>
          <upper>1e+16</upper>
        </limit>
        <dynamics>
          <spring_reference>0</spring_reference>
          <spring_stiffness>0</spring_stiffness>
        </dynamics>
      </axis>
    </joint>
    <link name='wheel_1'>
      <pose relative_to='axial_0_1'>0 0 0 0 -0 0</pose>
      <inertial>
        <pose>0 0 0 0 -0 0</pose>
        <mass>6.5</mass>
        <inertia>
          <ixx>0.058691</ixx>
          <ixy>0</ixy>
          <ixz>0</ixz>
          <iyy>0.058691</iyy>
          <iyz>0</iyz>
          <izz>0.10055</izz>
        </inertia>
      </inertial>
      <collision name='wheel_1_collision'>
        <pose>0 0 0 0 -0 0</pose>
        <geometry>
          <mesh>
            <scale>1 1 1</scale>
            <uri>model://sly/meshes/wheel_1.STL</uri>
          </mesh>
        </geometry>
      </collision>
      <visual name='wheel_1_visual'>
        <pose>0 0 0 0 -0 0</pose>
        <geometry>
          <mesh>
            <scale>1 1 1</scale>
            <uri>model://sly/meshes/wheel_1.STL</uri>
          </mesh>
        </geometry>
      </visual>
    </link>
    <joint name='axial_1_0' type='revolute'>
      <pose relative_to='base_link'>-0.2761 0.17448 0.1778 -1.5708 0 0</pose>
      <parent>base_link</parent>
      <child>wheel_2</child>
      <axis>
        <xyz>0 0 -1</xyz>
        <limit>
          <lower>-1e+16</lower>
          <upper>1e+16</upper>
        </limit>
        <dynamics>
          <spring_reference>0</spring_reference>
          <spring_stiffness>0</spring_stiffness>
        </dynamics>
      </axis>
    </joint>
    <link name='wheel_2'>
      <pose relative_to='axial_1_0'>0 0 0 0 -0 0</pose>
      <inertial>
        <pose>0 0 0 0 -0 0</pose>
        <mass>6.5</mass>
        <inertia>
          <ixx>0.058691</ixx>
          <ixy>0</ixy>
          <ixz>0</ixz>
          <iyy>0.058691</iyy>
          <iyz>0</iyz>
          <izz>0.10055</izz>
        </inertia>
      </inertial>
      <collision name='wheel_2_collision'>
        <pose>0 0 0 0 -0 0</pose>
        <geometry>
          <mesh>
            <scale>1 1 1</scale>
            <uri>model://sly/meshes/wheel_2.STL</uri>
          </mesh>
        </geometry>
      </collision>
      <visual name='wheel_2_visual'>
        <pose>0 0 0 0 -0 0</pose>
        <geometry>
          <mesh>
            <scale>1 1 1</scale>
            <uri>model://sly/meshes/wheel_2.STL</uri>
          </mesh>
        </geometry>
      </visual>
    </link>
    <joint name='axial_1_1' type='revolute'>
      <pose relative_to='base_link'>-0.2761 -0.17477 0.1778 -1.5708 0 0</pose>
      <parent>base_link</parent>
      <child>wheel_3</child>
      <axis>
        <xyz>0 0 -1</xyz>
        <limit>
          <lower>-1e+16</lower>
          <upper>1e+16</upper>
        </limit>
        <dynamics>
          <spring_reference>0</spring_reference>
          <spring_stiffness>0</spring_stiffness>
        </dynamics>
      </axis>
    </joint>
    <link name='wheel_3'>
      <pose relative_to='axial_1_1'>0 0 0 0 -0 0</pose>
      <inertial>
        <pose>0 0 0 0 -0 0</pose>
        <mass>6.5</mass>
        <inertia>
          <ixx>0.058691</ixx>
          <ixy>0</ixy>
          <ixz>0</ixz>
          <iyy>0.058691</iyy>
          <iyz>0</iyz>
          <izz>0.10055</izz>
        </inertia>
      </inertial>
      <collision name='wheel_3_collision'>
        <pose>0 0 0 0 -0 0</pose>
        <geometry>
          <mesh>
            <scale>1 1 1</scale>
            <uri>model://sly/meshes/wheel_3.STL</uri>
          </mesh>
        </geometry>
      </collision>
      <visual name='wheel_3_visual'>
        <pose>0 0 0 0 -0 0</pose>
        <geometry>
          <mesh>
            <scale>1 1 1</scale>
            <uri>model://sly/meshes/wheel_3.STL</uri>
          </mesh>
        </geometry>
      </visual>
    </link>
  </model>
</sdf>
